Workbook

Sheet Lauren no longer working
A1: March 2022 Monthly Budget
A2: Income: | B2: 1st half of month | C2: 2nd half of month | F2: what we make 1st half of month | G2: what we owe 1st half of month | H2: money left over
A3: Brian | B3: 3796.66 | C3: 3796.66 | F3: =B3+B4 -> 3796.66 | G3: =C9+C10+C11+C12+C13+C14+C15 -> 3528.31 | H3: =F3-G3 -> 268.35
A4: Lauren
F5: what we make 2nd half of month | G5: what we owe 2nd half of month | H5: money left over
F6: =B3+B4 -> 3796.66 | G6: =C18+C19+C20+C21+C22+C23 -> 1679.22 | H6: =F6-G6 -> 2117.44
A7: Expenses: | B7: Due Date: | C7: Expense Cost:
A8: 1st half of month:
A9: Mortgage Payment (automatic) | B9: 1st of each month | C9: 2271.33
A10: youtube tv (automatic) | B10: 1st of each month | C10: 64.99
A11: Starlink(automatic) | B11: 3rd of each month | C11: 110 | F11: Average for two week span
A12: Mohela Student Interest Loan (automatic) | B12: 6th of each month | C12: 542.02 | F12: =(H3+H6)/2 -> 1192.895
A13: Travlers Insurance | B13: 7th of each month | C13: 165.33
A14: Disney+(automatic) | B14: 13th of each month | C14: 8.55
A15: Toyota Financial Payment (automatic) | B15: 15th of each month | C15: 366.09
A17: 2nd half of month:
A18: Ram Truck Payment (automatic) | B18: 16th of each month | C18: 710.16
A19: Greenbrier Water, trash payment | B19: 18th of each month | C19: 47.1
A20: At&t Payment (automatic) | B20: 22nd of each month | C20: 243.86
A21: Entergy Payment (automatic) | B21: 27th of each month | C21: 313.4
A22: Pool Loan Payment(automatic) | B22: 26th of each month | C22: 342.81
A23: Netflix | B23: 28th of each month | C23: 21.89
A31: Arkansas Protection Services
A32: Spotify USA (automatic)
A33: Lawn Mower
A34: Lowes
A35: Synchrony Bank Payment - Mattress (automatic)

Sheet June 2022
A1: June 2022 Monthly Budget
A2: Income: | B2: 1st half of month | C2: 2nd half of month | F2: what we make 1st half of month | G2: what we owe 1st half of month | H2: money left over
A3: Brian | B3: 3796.66 | C3: 3796.66 | F3: =B3+B4 -> 5319.655 | G3: =C9+C10+C11+C12+C13+C14+C15+C16+C17 -> 3546.16 | H3: =F3-G3 -> 1773.495
A4: Lauren | B4: 1522.995 | C4: 1522.995
F5: what we make 2nd half of month | G5: what we owe 2nd half of month | H5: money left over
F6: =B3+B4 -> 5319.655 | G6: =C20+C21+C22+C23+C24+C25+C26+C27 -> 1775 | H6: =F6-G6 -> 3544.655
A7: Expenses: | B7: Due Date: | C7: Expense Cost:
A8: 1st half of month:
A9: Mortgage Payment (automatic) | B9: 1st of each month | C9: 2271.33
A10: youtube tv (automatic) | B10: 1st of each month | C10: 80.23
A11: Swyft Internet(automatic) | B11: 3rd of each month | C11: 98.39 | F11: Average for two week span
A12: Arkansas Protection Services | B12: Paid Quartly | F12: =(H3+H6)/2 -> 2659.075
A13: Mohela Student Interest Loan (automatic) | B13: 6th of each month | C13: 542.02
A14: Travlers Insurance | B14: 7th of each month | C14: 165.33
A15: Spotify USA (automatic) | B15: 9th of each month | C15: 14.22
A16: Disney+(automatic) | B16: 13th of each month | C16: 8.55
A17: Toyota Financial Payment (automatic) | B17: 15th of each month | C17: 366.09
A19: 2nd half of month:
A20: Ram Truck Payment (automatic) | B20: 16th of each month | C20: 710.16
A21: Greenbrier Water, trash payment | B21: 18th of each month | C21: 62.31
A22: At&t Payment (automatic) | B22: 22nd of each month | C22: 243.86
A23: Lawn Mower | B23: 29th of each month | C23: 120.67
A24: Entergy Payment (automatic) | B24: 27th of each month | C24: 204.3
A25: Pool Loan Payment(automatic) | B25: 26th of each month | C25: 342.81
A26: Synchrony Bank Payment - Mattress (automatic) | B26: 27th of each month | C26: 69
A27: Netflix | B27: 28th of each month | C27: 21.89
A40: Disney Trip Expenses | B40: Amount owed
A41: House | B41: 810
A42: Disney Tickets | B42: 1354.12
A43: Car Rental | B43: 477.36
A44: Universal Tickets | B44: 1398.05
B45: 4039.53

Sheet May 2022
A1: May 2022 Monthly Budget
A2: Income: | B2: 1st half of month | C2: 2nd half of month | F2: what we make 1st half of month | G2: what we owe 1st half of month | H2: money left over
A3: Brian | B3: 3796.66 | C3: 3796.66 | F3: =B3+B4 -> 5319.655 | G3: =C9+C10+C11+C12+C13+C14+C15+C16+C17 -> 3546.16 | H3: =F3-G3 -> 1773.495
A4: Lauren | B4: 1522.995 | C4: 1522.995
F5: what we make 2nd half of month | G5: what we owe 2nd half of month | H5: money left over
F6: =B3+B4 -> 5319.655 | G6: =C20+C21+C22+C23+C24+C25+C26+C27 -> 1782.68 | H6: =F6-G6 -> 3536.975
A7: Expenses: | B7: Due Date: | C7: Expense Cost:
A8: 1st half of month:
A9: Mortgage Payment (automatic) | B9: 1st of each month | C9: 2271.33
A10: youtube tv (automatic) | B10: 1st of each month | C10: 80.23
A11: Swyft Internet(automatic) | B11: 3rd of each month | C11: 98.39 | F11: Average for two week span
A12: Arkansas Protection Services | B12: Paid Quartly | F12: =(H3+H6)/2 -> 2655.235
A13: Mohela Student Interest Loan (automatic) | B13: 6th of each month | C13: 542.02
A14: Travlers Insurance | B14: 7th of each month | C14: 165.33
A15: Spotify USA (automatic) | B15: 9th of each month | C15: 14.22
A16: Disney+(automatic) | B16: 13th of each month | C16: 8.55
A17: Toyota Financial Payment (automatic) | B17: 15th of each month | C17: 366.09
A19: 2nd half of month:
A20: Ram Truck Payment (automatic) | B20: 16th of each month | C20: 710.16
A21: Greenbrier Water, trash payment | B21: 18th of each month | C21: 62.31
A22: At&t Payment (automatic) | B22: 22nd of each month | C22: 243.86
A23: Lawn Mower | B23: 29th of each month | C23: 120.67
A24: Entergy Payment (automatic) | B24: 27th of each month | C24: 211.98
A25: Pool Loan Payment(automatic) | B25: 26th of each month | C25: 342.81
A26: Synchrony Bank Payment - Mattress (automatic) | B26: 27th of each month | C26: 69
A27: Netflix | B27: 28th of each month | C27: 21.89
A40: Disney Trip Expenses | B40: Amount owed
A41: House | B41: 810
A42: Disney Tickets | B42: 1354.12
A43: Car Rental | B43: 477.36
A44: Universal Tickets | B44: 1398.05
B45: 4039.53

Sheet April 2022
A1: April 2022 Monthly Budget
A2: Income: | B2: 1st half of month | C2: 2nd half of month | F2: what we make 1st half of month | G2: what we owe 1st half of month | H2: money left over
A3: Brian | B3: 3796.66 | C3: 3796.66 | F3: =B3+B4 -> 5319.655 | G3: =C9+C10+C11+C12+C13+C14+C15+C16+C17 -> 3546.16 | H3: =F3-G3 -> 1773.495
A4: Lauren | B4: 1522.995 | C4: 1522.995
F5: what we make 2nd half of month | G5: what we owe 2nd half of month | H5: money left over
F6: =B3+B4 -> 5319.655 | G6: =C20+C21+C22+C23+C24+C25+C26+C27+C28 -> 2032.46 | H6: =F6-G6 -> 3287.195
A7: Expenses: | B7: Due Date: | C7: Expense Cost:
A8: 1st half of month:
A9: Mortgage Payment (automatic) | B9: 1st of each month | C9: 2271.33
A10: youtube tv (automatic) | B10: 1st of each month | C10: 80.23
A11: Swyft Internet(automatic) | B11: 3rd of each month | C11: 98.39 | F11: Average for two week span
A12: Arkansas Protection Services | B12: Paid Quartly | F12: =(H3+H6)/2 -> 2530.345
A13: Mohela Student Interest Loan (automatic) | B13: 6th of each month | C13: 542.02
A14: Travlers Insurance | B14: 7th of each month | C14: 165.33
A15: Spotify USA (automatic) | B15: 9th of each month | C15: 14.22
A16: Disney+(automatic) | B16: 13th of each month | C16: 8.55
A17: Toyota Financial Payment (automatic) | B17: 15th of each month | C17: 366.09
A19: 2nd half of month:
A20: Ram Truck Payment (automatic) | B20: 16th of each month | C20: 710.16
A21: Greenbrier Water, trash payment | B21: 18th of each month | C21: 47.1
A22: At&t Payment (automatic) | B22: 22nd of each month | C22: 243.86
A23: Lawn Mower | B23: 29th of each month | C23: 120.67
A24: Entergy Payment (automatic) | B24: 27th of each month | C24: 226.97
A25: Lowes | B25: 2nd half of the month | C25: 250
A26: Pool Loan Payment(automatic) | B26: 26th of each month | C26: 342.81
A27: Synchrony Bank Payment - Mattress (automatic) | B27: 27th of each month | C27: 69
A28: Netflix | B28: 28th of each month | C28: 21.89
A32: Credit cards: | B32: Amount owed | F32: Combined amount:
A33: Citi Card payment | B33: 0 | F33: 17144.66
A34: Lawn Mower | B34: 3378.53
A35: Lowes | B35: 0 | C35: pay 2567.19 on 4/18 | F35: Combined - normal pay
A36: Payment - Mattress (automatic) | B36: 2438 | F36: =F33-B3 -> 13348
A37: Amex | B37: 0
A38: Sams club Mastercard | B38: 0 | C38: pay 1727.18 on 4/18 | F38: Bonus - 2 week spending
A39: Amazon | B39: 0 | F39: =F36-800 -> 12548
A41: Disney Trip Expenses | B41: Amount owed
A42: House | B42: 810
A43: Disney Tickets | B43: 1354.12
A44: Car Rental | B44: 477.36
A45: Universal Tickets | B45: 1398.05
...

Sheet March 2022
A1: March 2022 Monthly Budget
A2: Income: | B2: 1st half of month | C2: 2nd half of month | F2: what we make 1st half of month | G2: what we owe 1st half of month | H2: money left over
A3: Brian | B3: 3796.66 | C3: 3796.66 | F3: =B3+B4 -> 5273.95 | G3: =C9+C10+C11+C12+C13+C14+C15+C16+C17 -> 3546.16 | H3: =F3-G3 -> 1727.79
A4: Lauren | B4: 1477.29 | C4: 1477.29
F5: what we make 2nd half of month | G5: what we owe 2nd half of month | H5: money left over
F6: =B3+B4 -> 5273.95 | G6: =C20+C21+C22+C23+C24+C25+C26+C27+C28 -> 2101.81 | H6: =F6-G6 -> 3172.14
A7: Expenses: | B7: Due Date: | C7: Expense Cost:
A8: 1st half of month:
A9: Mortgage Payment (automatic) | B9: 1st of each month | C9: 2271.33
A10: youtube tv (automatic) | B10: 1st of each month | C10: 80.23
A11: Swyft Internet(automatic) | B11: 3rd of each month | C11: 98.39 | F11: Average for two week span
A12: Arkansas Protection Services | B12: Paid Quartly | F12: =(H3+H6)/2 -> 2449.965
A13: Mohela Student Interest Loan (automatic) | B13: 6th of each month | C13: 542.02
A14: Travlers Insurance | B14: 7th of each month | C14: 165.33
A15: Spotify USA (automatic) | B15: 9th of each month | C15: 14.22
A16: Disney+(automatic) | B16: 13th of each month | C16: 8.55
A17: Toyota Financial Payment (automatic) | B17: 15th of each month | C17: 366.09
A19: 2nd half of month:
A20: Ram Truck Payment (automatic) | B20: 16th of each month | C20: 710.16
A21: Greenbrier Water, trash payment | B21: 18th of each month | C21: 47.1
A22: At&t Payment (automatic) | B22: 22nd of each month | C22: 243.86
A23: Lawn Mower | B23: 29th of each month | C23: 120.67
A24: Entergy Payment (automatic) | B24: 27th of each month | C24: 296.32
A25: Lowes | B25: 2nd half of the month | C25: 250
A26: Pool Loan Payment(automatic) | B26: 26th of each month | C26: 342.81
A27: Synchrony Bank Payment - Mattress (automatic) | B27: 27th of each month | C27: 69
A28: Netflix | B28: 28th of each month | C28: 21.89

Sheet February 2022
A1: January 2022 Monthly Budget
A2: Income: | B2: 1st half of month | C2: 2nd half of month | F2: what we make 1st half of month | G2: what we owe 1st half of month | H2: money left over
A3: Brian | B3: 3916.75 | C3: 3916.75 | F3: =B3+B4 -> 5391.46 | G3: =C9+C10+C11+C12+C13+C14+C15+C16+C17 -> 3546.16 | H3: =F3-G3 -> 1845.3
A4: Lauren | B4: 1474.71 | C4: 1474.71
F5: what we make 2nd half of month | G5: what we owe 2nd half of month | H5: money left over
F6: =B3+B4 -> 5391.46 | G6: =C20+C21+C22+C23+C24+C25+C26+C27+C28 -> 2116.7 | H6: =F6-G6 -> 3274.76
A7: Expenses: | B7: Due Date: | C7: Expense Cost:
A8: 1st half of month:
A9: Mortgage Payment (automatic) | B9: 1st of each month | C9: 2271.33
A10: youtube tv (automatic) | B10: 1st of each month | C10: 80.23
A11: Swyft Internet(automatic) | B11: 3rd of each month | C11: 98.39 | F11: Average for two week span
A12: Arkansas Protection Services | B12: Paid Quartly | F12: =(H3+H6)/2 -> 2560.03
A13: Mohela Student Interest Loan (automatic) | B13: 6th of each month | C13: 542.02
A14: Travlers Insurance | B14: 7th of each month | C14: 165.33
A15: Spotify USA (automatic) | B15: 9th of each month | C15: 14.22
A16: Disney+(automatic) | B16: 13th of each month | C16: 8.55
A17: Toyota Financial Payment (automatic) | B17: 15th of each month | C17: 366.09
A19: 2nd half of month:
A20: Ram Truck Payment (automatic) | B20: 16th of each month | C20: 710.16
A21: Greenbrier Water, trash payment | B21: 18th of each month | C21: 47.1
A22: At&t Payment (automatic) | B22: 22nd of each month | C22: 243.86
A23: Lawn Mower | B23: 29th of each month | C23: 120.67
A24: Entergy Payment (automatic) | B24: 27th of each month | C24: 313.4
A25: Lowes | B25: 2nd half of the month | C25: 250
A26: Pool Loan Payment(automatic) | B26: 26th of each month | C26: 342.81
A27: Synchrony Bank Payment - Mattress (automatic) | B27: 27th of each month | C27: 69
A28: Netflix | B28: 28th of each month | C28: 19.7

Sheet January 2022
A1: January 2022 Monthly Budget
A2: Income: | B2: 1st half of month | C2: 2nd half of month | F2: what we make 1st half of month | G2: what we owe 1st half of month | H2: money left over
A3: Brian | B3: 3879.35 | C3: 3879.35 | F3: =B3+B4 -> 5354.06 | G3: =C9+C10+C11+C12+C13+C14+C15+C16+C17+C18 -> 3809.16 | H3: =F3-G3 -> 1544.9
A4: Lauren | B4: 1474.71 | C4: 1474.71
F5: what we make 2nd half of month | G5: what we owe 2nd half of month | H5: money left over
F6: =B3+B4 -> 5354.06 | G6: =C21+C22+C23+C24+C25+C26+C27+C28+C29+C30 -> 2142.86 | H6: =F6-G6 -> 3211.2
A7: Expenses: | B7: Due Date: | C7: Expense Cost:
A8: 1st half of month:
A9: Mortgage Payment (automatic) | B9: 1st of each month | C9: 2271.33
A10: youtube tv (automatic) | B10: 1st of each month | C10: 80.23
A11: Swyft Internet(automatic) | B11: 3rd of each month | C11: 98.39 | F11: Average for two week span
A12: Arkansas Protection Services | B12: Paid Quartly | C12: 113 | F12: =(H3+H6)/2 -> 2378.05
A13: Mohela Student Interest Loan (automatic) | B13: 6th of each month | C13: 542.02
A14: Travlers Insurance | B14: 7th of each month | C14: 165.33
A15: Spotify USA (automatic) | B15: 9th of each month | C15: 14.22
A16: Disney+(automatic) | B16: 13th of each month | C16: 8.55
A17: Citi card payment | B17: 1st half of the month | C17: 150
A18: Toyota Financial Payment (automatic) | B18: 15th of each month | C18: 366.09
A20: 2nd half of month:
A21: Ram Truck Payment (automatic) | B21: 16th of each month | C21: 710.16
A22: Greenbrier Water, trash payment | B22: 18th of each month | C22: 62.5
A23: At&t Payment (automatic) | B23: 22nd of each month | C23: 243.86
A24: Lawn Mower | B24: 29th of each month | C24: 120.67
A25: Entergy Payment (automatic) | B25: 27th of each month | C25: 174.16
A26: Citi card payment | B26: 2nd half of the month | C26: 150
A27: Lowes | B27: 2nd half of the month | C27: 250
A28: Pool Loan Payment(automatic) | B28: 26th of each month | C28: 342.81
A29: Synchrony Bank Payment - Mattress (automatic) | B29: 27th of each month | C29: 69
A30: Netflix | B30: 28th of each month | C30: 19.7

Sheet December 2021
A1: December 2021 Monthly Budget
A2: Income: | B2: 1st half of month | C2: 2nd half of month | F2: what we make 1st half of month | G2: what we owe 1st half of month | H2: money left over
A3: Brian | B3: 3879.35 | C3: 3879.35 | F3: =B3+B4 -> 5354.06 | G3: =C9+C10+C11+C12+C13+C14+C15+C16+C17+C18 -> 3665.25 | H3: =F3-G3 -> 1688.81
A4: Lauren | B4: 1474.71 | C4: 1474.71
F5: what we make 2nd half of month | G5: what we owe 2nd half of month | H5: money left over
F6: =B3+B4 -> 5354.06 | G6: =C21+C22+C23+C24+C25+C26+C27+C28+C29+C30 -> 2149.52 | H6: =F6-G6 -> 3204.54
A7: Expenses: | B7: Due Date: | C7: Expense Cost:
A8: 1st half of month:
A9: Mortgage Payment (automatic) | B9: 1st of each month | C9: 2271.33
A10: youtube tv (automatic) | B10: 1st of each month | C10: 80.23
A11: Swyft Internet(automatic) | B11: 3rd of each month | C11: 98.39 | F11: Average for two week span
A12: Arkansas Protection Services | B12: Paid Quartly | F12: =(H3+H6)/2 -> 2446.675
A13: Mohela Student Interest Loan (automatic) | B13: 6th of each month | C13: 542.02
A14: Travlers Insurance | B14: 7th of each month | C14: 134.42
A15: Spotify USA (automatic) | B15: 9th of each month | C15: 14.22
A16: Disney+(automatic) | B16: 13th of each month | C16: 8.55
A17: Citi card payment | B17: 1st half of the month | C17: 150
A18: Toyota Financial Payment (automatic) | B18: 15th of each month | C18: 366.09
A20: 2nd half of month:
A21: Ram Truck Payment (automatic) | B21: 16th of each month | C21: 710.16
A22: Greenbrier Water, trash payment | B22: 18th of each month | C22: 57
A23: At&t Payment (automatic) | B23: 22nd of each month | C23: 243.86
A24: Lawn Mower | B24: 29th of each month | C24: 120.67
A25: Entergy Payment (automatic) | B25: 27th of each month | C25: 186.32
A26: Citi card payment | B26: 2nd half of the month | C26: 150
A27: Lowes | B27: 2nd half of the month | C27: 250
A28: Pool Loan Payment(automatic) | B28: 26th of each month | C28: 342.81
A29: Synchrony Bank Payment - Mattress (automatic) | B29: 27th of each month | C29: 69
A30: Netflix | B30: 28th of each month | C30: 19.7

Sheet November 2021
A1: November 2021 Monthly Budget
A2: Income: | B2: 1st half of month | C2: 2nd half of month | F2: what we make 1st half of month | G2: what we owe 1st half of month | H2: money left over
A3: Brian | B3: 3879.35 | C3: 3879.35 | F3: =B3+B4 -> 5354.06 | G3: =C9+C10+C11+C12+C13+C14+C15+C16+C17+C18 -> 3665.25 | H3: =F3-G3 -> 1688.81
A4: Lauren | B4: 1474.71 | C4: 1474.71
F5: what we make 2nd half of month | G5: what we owe 2nd half of month | H5: money left over
F6: =B3+B4 -> 5354.06 | G6: =C21+C22+C23+C24+C25+C26+C27+C28+C29+C30 -> 2145.26 | H6: =F6-G6 -> 3208.8
A7: Expenses: | B7: Due Date: | C7: Expense Cost:
A8: 1st half of month:
A9: Mortgage Payment (automatic) | B9: 1st of each month | C9: 2271.33
A10: youtube tv (automatic) | B10: 1st of each month | C10: 80.23
A11: Swyft Internet(automatic) | B11: 3rd of each month | C11: 98.39 | F11: Average for two week span
A12: Arkansas Protection Services | B12: Paid Quartly | F12: =(H3+H6)/2 -> 2448.805
A13: Mohela Student Interest Loan (automatic) | B13: 6th of each month | C13: 542.02
A14: Travlers Insurance | B14: 7th of each month | C14: 134.42
A15: Spotify USA (automatic) | B15: 9th of each month | C15: 14.22
A16: Disney+(automatic) | B16: 13th of each month | C16: 8.55
A17: Citi card payment | B17: 1st half of the month | C17: 150
A18: Toyota Financial Payment (automatic) | B18: 15th of each month | C18: 366.09
A20: 2nd half of month:
A21: Ram Truck Payment (automatic) | B21: 16th of each month | C21: 710.16
A22: Greenbrier Water, trash payment | B22: 18th of each month | C22: 62.63
A23: At&t Payment (automatic) | B23: 22nd of each month | C23: 210.75
A24: Lawn Mower | B24: 29th of each month | C24: 120.67
A25: Entergy Payment (automatic) | B25: 27th of each month | C25: 209.54
A26: Citi card payment | B26: 2nd half of the month | C26: 150
A27: Lowes | B27: 2nd half of the month | C27: 250
A28: Pool Loan Payment(automatic) | B28: 26th of each month | C28: 342.81
A29: Synchrony Bank Payment - Mattress (automatic) | B29: 27th of each month | C29: 69
A30: Netflix | B30: 28th of each month | C30: 19.7
F33: Citi Card payment | G33: 6166.33
F34: Lawn Mower | G34: 4102.55
F35: Lowes | G35: 397
F36: Payment - Mattress (automatic) | G36: 2852
F37: Amex | G37: 0

Sheet October 2021
A1: October 2021 Monthly Budget
A2: Income: | B2: 1st half of month | C2: 2nd half of month | F2: what we make 1st half of month | G2: what we owe 1st half of month | H2: money left over
A3: Brian | B3: 3879.35 | C3: 3879.35 | F3: =B3+B4 -> 5354.06 | G3: =C9+C10+C11+C12+C13+C14+C15+C16+C17+C18 -> 3705.25 | H3: =F3-G3 -> 1648.81
A4: Lauren | B4: 1474.71 | C4: 1474.71
F5: what we make 2nd half of month | G5: what we owe 2nd half of month | H5: money left over
F6: =B3+B4 -> 5354.06 | G6: =C21+C22+C23+C24+C25+C26+C27+C28+C29+C30 -> 2320.27 | H6: =F6-G6 -> 3033.79
A7: Expenses: | B7: Due Date: | C7: Expense Cost:
A8: 1st half of month:
A9: Mortgage Payment (automatic) | B9: 1st of each month | C9: 2271.33
A10: youtube tv (automatic) | B10: 1st of each month | C10: 80.23
A11: Swyft Internet(automatic) | B11: 3rd of each month | C11: 98.39 | F11: Average for two week span
A12: Arkansas Protection Services | B12: Paid Quartly | C12: 40 | F12: =(H3+H6)/2 -> 2341.3
A13: Mohela Student Interest Loan (automatic) | B13: 6th of each month | C13: 542.02
A14: Travlers Insurance | B14: 7th of each month | C14: 134.42
A15: Spotify USA (automatic) | B15: 9th of each month | C15: 14.22
A16: Disney+(automatic) | B16: 13th of each month | C16: 8.55
A17: Citi card payment | B17: 1st half of the month | C17: 150
A18: Toyota Financial Payment (automatic) | B18: 15th of each month | C18: 366.09
A20: 2nd half of month:
A21: Ram Truck Payment (automatic) | B21: 16th of each month | C21: 710.16
A22: Greenbrier Water, trash payment | B22: 18th of each month | C22: 62.63
A23: At&t Payment (automatic) | B23: 22nd of each month | C23: 210.75
A24: Lawn Mower | B24: 29th of each month | C24: 120.67
A25: Entergy Payment (automatic) | B25: 27th of each month | C25: 384.55
A26: Citi card payment | B26: 2nd half of the month | C26: 150
A27: Lowes | B27: 2nd half of the month | C27: 250
A28: Pool Loan Payment(automatic) | B28: 26th of each month | C28: 342.81
A29: Synchrony Bank Payment - Mattress (automatic) | B29: 27th of each month | C29: 69
A30: Netflix | B30: 28th of each month | C30: 19.7
F33: Citi Card payment | G33: 6166.33
F34: Lawn Mower | G34: 4102.55
F35: Lowes | G35: 0
F36: Payment - Mattress (automatic) | G36: 2852
F37: Amex | G37: 0
B39: 13120.88 % 739.67
B40: 17.7 months to save this much up

Sheet September 2021
A1: September 2021 Monthly Budget
A2: Income: | B2: 1st half of month | C2: 2nd half of month | F2: what we make 1st half of month | G2: what we owe 1st half of month | H2: money left over
A3: Brian | B3: 3879.35 | C3: 3879.35 | F3: =B3+B4 -> 5354.06 | G3: =C9+C10+C11+C12+C13+C14+C15+C16+C17+C18 -> 3694.4 | H3: =F3-G3 -> 1659.66
A4: Lauren | B4: 1474.71 | C4: 1474.71
F5: what we make 2nd half of month | G5: what we owe 2nd half of month | H5: money left over
F6: =B3+B4 -> 5354.06 | G6: =C21+C22+C23+C24+C25+C26+C27+C28+C29+C30 -> 2351.28 | H6: =F6-G6 -> 3002.78
A7: Expenses: | B7: Due Date: | C7: Expense Cost:
A8: 1st half of month:
A9: Mortgage Payment (automatic) | B9: 1st of each month | C9: 2271.33
A10: youtube tv (automatic) | B10: 1st of each month | C10: 69.59
A11: Swyft Internet(automatic) | B11: 3rd of each month | C11: 98.74 | F11: Average for two week span
A12: Arkansas Protection Services | B12: Paid Quartly | C12: 40 | F12: =(H3+H6)/2 -> 2331.22
A13: Mohela Student Interest Loan (automatic) | B13: 6th of each month | C13: 542.02
A14: Travlers Insurance | B14: 7th of each month | C14: 134.42
A15: Spotify USA (automatic) | B15: 9th of each month | C15: 14.22
A16: Disney+(automatic) | B16: 13th of each month | C16: 7.99
A17: Citi card payment | B17: 1st half of the month | C17: 150
A18: Toyota Financial Payment (automatic) | B18: 15th of each month | C18: 366.09
A20: 2nd half of month:
A21: Ram Truck Payment (automatic) | B21: 16th of each month | C21: 710.16
A22: Greenbrier Water, trash payment | B22: 18th of each month | C22: 88.93
A23: At&t Payment (automatic) | B23: 22nd of each month | C23: 210.75
A24: Lawn Mower | B24: 29th of each month | C24: 120.67
A25: Entergy Payment (automatic) | B25: 27th of each month | C25: 389.26
A26: Citi card payment | B26: 2nd half of the month | C26: 150
A27: Lowes | B27: 2nd half of the month | C27: 250
A28: Pool Loan Payment(automatic) | B28: 26th of each month | C28: 342.81
A29: Synchrony Bank Payment - Mattress (automatic) | B29: 27th of each month | C29: 69
A30: Netflix | B30: 28th of each month | C30: 19.7

Sheet August 2021
A1: August 2021 Monthly Budget
A2: Income: | B2: 1st half of month | C2: 2nd half of month | F2: what we make 1st half of month | G2: what we owe 1st half of month | H2: money left over
A3: Brian | B3: 3439.14 | C3: 3439.14 | F3: =B3+B4 -> 4913.85 | G3: =C9+C10+C11+C12+C13+C14+C15+C16+C17+C18 -> 3648.68 | H3: =F3-G3 -> 1265.17
A4: Lauren | B4: 1474.71 | C4: 1474.71
F5: what we make 2nd half of month | G5: what we owe 2nd half of month | H5: money left over
F6: =B3+B4 -> 4913.85 | G6: =C21+C22+C23+C24+C25+C26+C27+C28+C29+C30 -> 2337.94 | H6: =F6-G6 -> 2575.91
A7: Expenses: | B7: Due Date: | C7: Expense Cost:
A8: 1st half of month:
A9: Mortgage Payment (automatic) | B9: 1st of each month | C9: 2225.61
A10: youtube tv (automatic) | B10: 1st of each month | C10: 69.59
A11: Swyft Internet(automatic) | B11: 3rd of each month | C11: 98.74 | F11: Average for two week span
A12: Arkansas Protection Services | B12: Paid Quartly | C12: 40 | F12: =(H3+H6)/2 -> 1920.54
A13: Mohela Student Interest Loan (automatic) | B13: 6th of each month | C13: 542.02
A14: Travlers Insurance | B14: 7th of each month | C14: 134.42
A15: Spotify USA (automatic) | B15: 9th of each month | C15: 14.22
A16: Disney+(automatic) | B16: 13th of each month | C16: 7.99
A17: Citi card payment | B17: 1st half of the month | C17: 150
A18: Toyota Financial Payment (automatic) | B18: 15th of each month | C18: 366.09
A20: 2nd half of month:
A21: Ram Truck Payment (automatic) | B21: 16th of each month | C21: 710.16
A22: Greenbrier Water, trash payment | B22: 18th of each month | C22: 88.93
A23: At&t Payment (automatic) | B23: 22nd of each month | C23: 210.75
A24: Lawn Mower | B24: 29th of each month | C24: 120.67
A25: Entergy Payment (automatic) | B25: 27th of each month | C25: 376.45
A26: Citi card payment | B26: 2nd half of the month | C26: 150
A27: Lowes | B27: 2nd half of the month | C27: 250
A28: Pool Loan Payment(automatic) | B28: 26th of each month | C28: 342.81
A29: Synchrony Bank Payment - Mattress (automatic) | B29: 27th of each month | C29: 69
A30: Netflix | B30: 28th of each month | C30: 19.17

Sheet July 2021
A1: July 2021 Monthly Budget
A2: Income: | B2: 1st half of month | C2: 2nd half of month | F2: what we make 1st half of month | G2: what we owe 1st half of month | H2: money left over
A3: Brian | B3: 3439.14 | C3: 3439.14 | F3: =B3+B4 -> 4880.67 | G3: =C9+C10+C11+C12+C13+C14+C15+C16+C17+C18 -> 3670.68 | H3: =F3-G3 -> 1209.99
A4: Lauren | B4: 1441.53 | C4: 1441.53
F5: what we make 2nd half of month | G5: what we owe 2nd half of month | H5: money left over
F6: =B3+B4 -> 4880.67 | G6: =C21+C22+C23+C24+C25+C26+C27+C28+C29+C30 -> 2041 | H6: =F6-G6 -> 2839.67
A7: Expenses: | B7: Due Date: | C7: Expense Cost:
A8: 1st half of month:
A9: Mortgage Payment (automatic) | B9: 1st of each month | C9: 2256.87
A10: youtube tv (automatic) | B10: 1st of each month | C10: 69.59
A11: Swyft Internet(automatic) | B11: 3rd of each month | C11: 98.74 | F11: Average for two week span
A12: Arkansas Protection Services | B12: Paid Quartly | C12: 40 | F12: =(H3+H6)/2 -> 2024.83
A13: Mohela Student Interest Loan (automatic) | B13: 6th of each month | C13: 542.02
A14: Travlers Insurance | B14: 7th of each month | C14: 125.16
A15: Spotify USA (automatic) | B15: 9th of each month | C15: 14.22
A16: Disney+(automatic) | B16: 13th of each month | C16: 7.99
A17: Citi card payment | B17: 1st half of the month | C17: 150
A18: Toyota Financial Payment (automatic) | B18: 15th of each month | C18: 366.09
A20: 2nd half of month:
A21: Tahoe Payment (automatic) | B21: 16th of each month | C21: 483.15
A22: Greenbrier Water, trash payment | B22: 18th of each month | C22: 55
A23: At&t Payment (automatic) | B23: 22nd of each month | C23: 210.75
A24: Lawn Mower | B24: 29th of each month | C24: 120.67
A25: Entergy Payment (automatic) | B25: 27th of each month | C25: 340.45
A26: Citi card payment | B26: 2nd half of the month | C26: 150
A27: Lowes | B27: 2nd half of the month | C27: 250
A28: Pool Loan Payment(automatic) | B28: 26th of each month | C28: 342.81
A29: Synchrony Bank Payment - Mattress (automatic) | B29: 27th of each month | C29: 69
A30: Netflix | B30: 28th of each month | C30: 19.17

Sheet June 2021
A1: June 2021 Monthly Budget
A2: Income: | B2: 1st half of month | C2: 2nd half of month | F2: what we make 1st half of month | G2: what we owe 1st half of month | H2: money left over
A3: Brian | B3: 3439.14 | C3: 3439.14 | F3: =B3+B4 -> 4880.67 | G3: =C9+C10+C11+C12+C13+C14+C15+C16+C17+C18 -> 3618.2 | H3: =F3-G3 -> 1262.47
A4: Lauren | B4: 1441.53 | C4: 1441.53
F5: what we make 2nd half of month | G5: what we owe 2nd half of month | H5: money left over
F6: =B3+B4 -> 4880.67 | G6: =C21+C22+C23+C24+C25+C26+C27+C28+C29 -> 1762.55 | H6: =F6-G6 -> 3118.12
A7: Expenses: | B7: Due Date: | C7: Expense Cost:
A8: 1st half of month:
A9: Mortgage Payment (automatic) | B9: 1st of each month | C9: 2256.87
A10: youtube tv (automatic) | B10: 1st of each month | C10: 69.59
A11: Swyft Internet(automatic) | B11: 3rd of each month | C11: 98.74 | F11: Average for two week span
A12: Arkansas Protection Services | B12: Paid Quartly | C12: 40 | F12: =(H3+H6)/2 -> 2190.295
A13: Mohela Student Interest Loan (automatic) | B13: 6th of each month | C13: 542.02
A14: Travlers Insurance | B14: 7th of each month | C14: 72.68
A15: Spotify USA (automatic) | B15: 9th of each month | C15: 14.22
A16: Disney+(automatic) | B16: 13th of each month | C16: 7.99
A17: Citi card payment | B17: 1st half of the month | C17: 150
A18: Toyota Financial Payment (automatic) | B18: 15th of each month | C18: 366.09
A20: 2nd half of month: | F20: 11373.01
A21: Tahoe Payment (automatic) | B21: 16th of each month | C21: 483.15
A22: Greenbrier Water, trash payment | B22: 18th of each month | C22: 55
A23: At&t Payment (automatic) | B23: 22nd of each month | C23: 210.75
A24: Lawn Mower | B24: 29th of each month | C24: 120.67
A25: Pool Loan Payment(automatic) | B25: 26th of each month | C25: 342.81
A26: Entergy Payment (automatic) | B26: 27th of each month | C26: 131
A27: Citi card payment | B27: 2nd half of the month | C27: 150
A28: Lowes | B28: 2nd half of the month | C28: 250
A29: Netflix | B29: 28th of each month | C29: 19.17
B33: What we owe | C33: Amount we pay a month
A34: Synchrony Bank Payment - Mattress (automatic) | B34: 4025 | C34: 69

Sheet May 2021
A1: May 2021 Monthly Budget
A2: Income: | B2: 1st half of month | C2: 2nd half of month | F2: what we make 1st half of month | G2: what we owe 1st half of month | H2: money left over
A3: Brian | B3: 3439.14 | C3: 3439.14 | F3: =B3+B4 -> 4880.67 | G3: =C9+C10+C11+C12+C13+C14+C15+C16+C17 -> 3101.11 | H3: =F3-G3 -> 1779.56
A4: Lauren | B4: 1441.53 | C4: 1441.53
F5: what we make 2nd half of month | G5: what we owe 2nd half of month | H5: money left over
F6: =B3+B4 -> 4880.67 | G6: =C20+C21+C22+C23+C24+C25+C26 -> 1381.24 | H6: =F6-G6 -> 3499.43
A7: Expenses: | B7: Due Date: | C7: Expense Cost:
A8: 1st half of month:
A9: Mortgage Payment (automatic) | B9: 1st of each month | C9: 2256.87
A10: youtube tv (automatic) | B10: 1st of each month | C10: 69.59
A11: Swyft Internet(automatic) | B11: 3rd of each month | C11: 98.74 | F11: Average for two week span
A12: Arkansas Protection Services | B12: Paid Quartly | C12: 40 | F12: =(H3+H6)/2 -> 2639.495
A13: Mohela Student Interest Loan (automatic) | B13: 6th of each month | C13: 542.02
A14: Travlers Insurance | B14: 7th of each month | C14: 72.68
A15: Spotify USA (automatic) | B15: 9th of each month | C15: 14.22
A17: Disney+(automatic) | B17: 13th of each month | C17: 6.99
A19: 2nd half of month:
A20: Tahoe Payment (automatic) | B20: 16th of each month | C20: 483.15
A21: Greenbrier Water, trash payment | B21: 18th of each month | C21: 73.69
A22: At&t Payment (automatic) | B22: 22nd of each month | C22: 210.75
A23: Lawn Mower | B23: 29th of each month | C23: 120.67
A24: Pool Loan Payment(automatic) | B24: 26th of each month | C24: 342.81
A25: Entergy Payment (automatic) | B25: 27th of each month | C25: 131
A26: Netflix | B26: 28th of each month | C26: 19.17
B30: What we owe | C30: Amount we pay a month
A31: Synchrony Bank Payment - Mattress (automatic) | B31: 4025 | C31: 69

Sheet April 2021
A1: April 2021 Monthly Budget
A2: Income: | B2: 1st half of month | C2: 2nd half of month | F2: what we make 1st half of month | G2: what we owe 1st half of month | H2: money left over
A3: Brian | B3: 3439.14 | C3: 3439.14 | F3: =B3+B4 -> 4880.67 | G3: =C9+C10+C11+C12+C13+C14+C15+C16+C17 -> 3617.06 | H3: =F3-G3 -> 1263.61
A4: Lauren | B4: 1441.53 | C4: 1441.53
F5: what we make 2nd half of month | G5: what we owe 2nd half of month | H5: money left over
F6: =B3+B4 -> 4880.67 | G6: =C20+C21+C22+C23+C24+C25+C26 -> 1367.16 | H6: =F6-G6 -> 3513.51
A7: Expenses: | B7: Due Date: | C7: Expense Cost:
A8: 1st half of month:
A9: Mortgage Payment (automatic) | B9: 1st of each month | C9: 2256.87
A10: youtube tv (automatic) | B10: 1st of each month | C10: 69.59
A11: Swyft Internet(automatic) | B11: 3rd of each month | C11: 98.74 | F11: Average for two week span
A12: Arkansas Protection Services | B12: Paid Quartly | C12: 40 | F12: =(H3+H6)/2 -> 2388.56
A13: Mohela Student Interest Loan (automatic) | B13: 6th of each month | C13: 542.02
A14: Travlers Insurance | B14: 7th of each month | C14: 154.66
A15: Spotify USA (automatic) | B15: 9th of each month | C15: 14.18
A16: BBVA Finance (automatic) | B16: 12th of each month | C16: 434.01
A17: Disney+(automatic) | B17: 13th of each month | C17: 6.99
A19: 2nd half of month:
A20: Tahoe Payment (automatic) | B20: 16th of each month | C20: 483.15
A21: Greenbrier Water, trash payment | B21: 18th of each month | C21: 52
A22: At&t Payment (automatic) | B22: 22nd of each month | C22: 210.75
A23: Lawn Mower | B23: 29th of each month | C23: 120.67
A24: Pool Loan Payment(automatic) | B24: 26th of each month | C24: 342.81
A25: Entergy Payment (automatic) | B25: 27th of each month | C25: 138.61
A26: Netflix | B26: 28th of each month | C26: 19.17
B30: What we owe | C30: Amount we pay a month
A31: Synchrony Bank Payment - Mattress (automatic) | B31: 4025 | C31: 69

Sheet March 2021
A1: March 2021 Monthly Budget
A2: Income: | B2: 1st half of month | C2: 2nd half of month | F2: what we make 1st half of month | G2: what we owe 1st half of month | H2: money left over
A3: Brian | B3: 3337.25 | C3: 3337.25 | F3: =B3+B4 -> 4778.78 | G3: =C9+C10+C11+C12+C13+C14+C15+C16+C17 -> 3617.06 | H3: =F3-G3 -> 1161.72
A4: Lauren | B4: 1441.53 | C4: 1441.53
F5: what we make 2nd half of month | G5: what we owe 2nd half of month | H5: money left over
F6: =B3+B4 -> 4778.78 | G6: =C20+C21+C22+C23+C24+C25+C26 -> 1484.15 | H6: =F6-G6 -> 3294.63
A7: Expenses: | B7: Due Date: | C7: Expense Cost:
A8: 1st half of month:
A9: Mortgage Payment (automatic) | B9: 1st of each month | C9: 2256.87
A10: youtube tv (automatic) | B10: 1st of each month | C10: 69.59
A11: Swyft Internet(automatic) | B11: 3rd of each month | C11: 98.74 | F11: Average for two week span
A12: Arkansas Protection Services | B12: Paid Quartly | C12: 40 | F12: =(H3+H6)/2 -> 2228.175
A13: Mohela Student Interest Loan (automatic) | B13: 6th of each month | C13: 542.02
A14: Travlers Insurance | B14: 7th of each month | C14: 154.66
A15: Spotify USA (automatic) | B15: 9th of each month | C15: 14.18
A16: BBVA Finance (automatic) | B16: 12th of each month | C16: 434.01
A17: Disney+(automatic) | B17: 13th of each month | C17: 6.99
A19: 2nd half of month:
A20: Tahoe Payment (automatic) | B20: 16th of each month | C20: 483.15
A21: Greenbrier Water, trash payment | B21: 18th of each month | C21: 52
A22: At&t Payment (automatic) | B22: 22nd of each month | C22: 210.75
A23: Lawn Mower | B23: 29th of each month | C23: 120.67
A24: Pool Loan Payment(automatic) | B24: 26th of each month | C24: 342.81
A25: Entergy Payment (automatic) | B25: 27th of each month | C25: 255.6
A26: Netflix | B26: 28th of each month | C26: 19.17
B30: What we owe | C30: Amount we pay a month
A31: Synchrony Bank Payment - Mattress (automatic) | B31: 4025 | C31: 69

Sheet February 2021
A1: February 2021 Monthly Budget
A2: Income: | B2: 1st half of month | C2: 2nd half of month | F2: what we make 1st half of month | G2: what we owe 1st half of month | H2: money left over
A3: Brian | B3: 3337.25 | C3: 3337.25 | F3: =B3+B4 -> 4778.78 | G3: =C9+C10+C11+C12+C13+C14+C15+C16+C17 -> 3617.06 | H3: =F3-G3 -> 1161.72
A4: Lauren | B4: 1441.53 | C4: 1441.53
F5: what we make 2nd half of month | G5: what we owe 2nd half of month | H5: money left over
F6: =B3+B4 -> 4778.78 | G6: =C20+C21+C22+C23+C24+C25+C26 -> 1501.18 | H6: =F6-G6 -> 3277.6
A7: Expenses: | B7: Due Date: | C7: Expense Cost:
A8: 1st half of month:
A9: Mortgage Payment (automatic) | B9: 1st of each month | C9: 2256.87
A10: youtube tv (automatic) | B10: 1st of each month | C10: 69.59
A11: Swyft Internet(automatic) | B11: 3rd of each month | C11: 98.74 | F11: Average for two week span
A12: Arkansas Protection Services | B12: Paid Quartly | C12: 40 | F12: =(H3+H6)/2 -> 2219.66
A13: Mohela Student Interest Loan (automatic) | B13: 6th of each month | C13: 542.02
A14: Travlers Insurance | B14: 7th of each month | C14: 154.66
A15: Spotify USA (automatic) | B15: 9th of each month | C15: 14.18
A16: BBVA Finance (automatic) | B16: 12th of each month | C16: 434.01
A17: Disney+(automatic) | B17: 13th of each month | C17: 6.99
A19: 2nd half of month:
A20: Tahoe Payment (automatic) | B20: 16th of each month | C20: 483.15
A21: Greenbrier Water, trash payment | B21: 18th of each month | C21: 52
A22: At&t Payment (automatic) | B22: 22nd of each month | C22: 210.75
A23: Lawn Mower | B23: 29th of each month | C23: 120.67
A24: Pool Loan Payment(automatic) | B24: 26th of each month | C24: 342.81
A25: Entergy Payment (automatic) | B25: 27th of each month | C25: 272.63
A26: Netflix | B26: 28th of each month | C26: 19.17
B30: What we owe | C30: Amount we pay a month
A31: Synchrony Bank Payment - Mattress (automatic) | B31: 4025 | C31: 69

Sheet January 2021
A1: January 2021 Monthly Budget
A2: Income: | B2: 1st half of month | C2: 2nd half of month | F2: what we make 1st half of month | G2: what we owe 1st half of month | H2: money left over
A3: Brian | B3: 3337.25 | C3: 3337.25 | F3: =B3+B4 -> 4778.78 | G3: =C9+C10+C11+C12+C13+C14+C15+C16+C17 -> 3595.84 | H3: =F3-G3 -> 1182.94
A4: Lauren | B4: 1441.53 | C4: 1441.53
F5: what we make 2nd half of month | G5: what we owe 2nd half of month | H5: money left over
F6: =B3+B4 -> 4778.78 | G6: =C20+C21+C22+C23+C24+C25+C26 -> 1398.99 | H6: =F6-G6 -> 3379.79
A7: Expenses: | B7: Due Date: | C7: Expense Cost:
A8: 1st half of month:
A9: Mortgage Payment (automatic) | B9: 1st of each month | C9: 2256.87
A10: direct tv payment (automatic) | B10: 1st of each month | C10: 55
A11: Swyft Internet(automatic) | B11: 3rd of each month | C11: 98.74 | F11: Average for two week span
A12: Arkansas Protection Services | B12: Paid Quartly | C12: 40 | F12: =(H3+H6)/2 -> 2281.365
A13: Mohela Student Interest Loan (automatic) | B13: 6th of each month | C13: 542.02
A14: Travlers Insurance | B14: 7th of each month | C14: 148.03
A15: Spotify USA (automatic) | B15: 9th of each month | C15: 14.18
A16: BBVA Finance (automatic) | B16: 12th of each month | C16: 434.01
A17: Disney+(automatic) | B17: 13th of each month | C17: 6.99
A19: 2nd half of month:
A20: Tahoe Payment (automatic) | B20: 16th of each month | C20: 483.15
A21: Greenbrier Water, trash payment | B21: 18th of each month | C21: 52
A22: At&t Payment (automatic) | B22: 22nd of each month | C22: 210.75
A23: Pool Loan Payment(automatic) | B23: 26th of each month | C23: 342.81
A24: Entergy Payment (automatic) | B24: 27th of each month | C24: 170.44
A25: Netflix | B25: 28th of each month | C25: 19.17
A26: Lawn Mower | B26: 29th of each month | C26: 120.67
B30: What we owe | C30: Amount we pay a month | G30: 5185.11 + 1635.06 = 6,820.17
A31: Synchrony Bank Payment - Mattress (automatic) | B31: 4025 | C31: 69 | G31: ((6674.5 + 2883.06) - 1600 ) - 740 = 7,217.56
G32: after christmas spending payments = 397.39

Sheet December 2020
A1: December 2020 Monthly Budget
A2: Income: | B2: 1st half of month | C2: 2nd half of month | F2: what we make 1st half of month | G2: what we owe 1st half of month | H2: money left over
A3: Brian | B3: 3337.25 | C3: 3337.25 | F3: =B3+B4 -> 4778.78 | G3: =C9+C10+C11+C12+C13+C14+C15+C16+C17 -> 3595.84 | H3: =F3-G3 -> 1182.94
A4: Lauren | B4: 1441.53 | C4: 1441.53
F5: what we make 2nd half of month | G5: what we owe 2nd half of month | H5: money left over
F6: =B3+B4 -> 4778.78 | G6: =C20+C21+C22+C23+C24+C25+C26 -> 1349.83 | H6: =F6-G6 -> 3428.95
A7: Expenses: | B7: Due Date: | C7: Expense Cost:
A8: 1st half of month:
A9: Mortgage Payment (automatic) | B9: 1st of each month | C9: 2256.87
A10: direct tv payment (automatic) | B10: 1st of each month | C10: 55
A11: Swyft Internet(automatic) | B11: 3rd of each month | C11: 98.74 | F11: Average for two week span
A12: Arkansas Protection Services | B12: Paid Quartly | C12: 40 | F12: =(H3+H6)/2 -> 2305.945
A13: Mohela Student Interest Loan (automatic) | B13: 6th of each month | C13: 542.02
A14: Travlers Insurance | B14: 7th of each month | C14: 148.03
A15: Spotify USA (automatic) | B15: 9th of each month | C15: 14.18
A16: BBVA Finance (automatic) | B16: 12th of each month | C16: 434.01
A17: Disney+(automatic) | B17: 13th of each month | C17: 6.99
A19: 2nd half of month:
A20: Tahoe Payment (automatic) | B20: 16th of each month | C20: 483.15
A21: Greenbrier Water, trash payment | B21: 18th of each month | C21: 52
A22: At&t Payment (automatic) | B22: 22nd of each month | C22: 212.75
A23: Pool Loan Payment(automatic) | B23: 26th of each month | C23: 342.81
A24: Entergy Payment (automatic) | B24: 27th of each month | C24: 120.94
A25: Netflix | B25: 28th of each month | C25: 17.51
A26: Lawn Mower | B26: 29th of each month | C26: 120.67
B30: What we owe | C30: Amount we pay a month
A31: Synchrony Bank Payment - Mattress (automatic) | B31: 4025 | C31: 69

Sheet November 2020
A1: November 2020 Monthly Budget
A2: Income: | B2: 1st half of month | C2: 2nd half of month | F2: what we make 1st half of month | G2: what we owe 1st half of month | H2: money left over
A3: Brian | B3: 3337.25 | C3: 3337.25 | F3: =B3+B4 -> 4778.78 | G3: =C9+C10+C11+C12+C13+C14+C15 -> 3442.1 | H3: =F3-G3 -> 1336.68
A4: Lauren | B4: 1441.53 | C4: 1441.53
F5: what we make 2nd half of month | G5: what we owe 2nd half of month | H5: money left over
F6: =B3+B4 -> 4778.78 | G6: =C18+C19+C20+C21+C22+C23+C24+C25+C26 -> 1781.58 | H6: =F6-G6 -> 2997.2
A7: Expenses: | B7: Due Date: | C7: Expense Cost:
A8: 1st half of month:
A9: Mortgage Payment (automatic) | B9: 1st of each month | C9: 2256.87
A10: Arkansas Protection Services | B10: Paid Quartly | C10: 40
A11: Mohela Student Interest Loan (automatic) | B11: 6th of each month | C11: 542.02 | F11: Average for two week span
A12: Travlers Insurance | B12: 7th of each month | C12: 148.03 | F12: =(H3+H6)/2 -> 2166.94
A13: Spotify USA (automatic) | B13: 9th of each month | C13: 14.18
A14: BBVA Finance (automatic) | B14: 12th of each month | C14: 434.01
A15: Disney+(automatic) | B15: 13th of each month | C15: 6.99
A17: 2nd half of month:
A18: Swyft Internet(automatic) | B18: 15th of each month | C18: 98.74
A19: Tahoe Payment (automatic) | B19: 16th of each month | C19: 483.15
A20: Greenbrier Water, trash payment | B20: 18th of each month | C20: 80
A21: At&t Payment (automatic) | B21: 22nd of each month | C21: 212.75
A22: youtube tv (automatic) | B22: 23rd of each month | C22: 69.54 | G22: 6924.36
A23: Pool Loan Payment(automatic) | B23: 26th of each month | C23: 342.81 | G23: 1119.69
A24: Entergy Payment (automatic) | B24: 27th of each month | C24: 356.41 | G24: 5804.67
A25: Netflix | B25: 28th of each month | C25: 17.51
A26: Lawn Mower | B26: 29th of each month | C26: 120.67 | G26: 5804.67
G27: 3442.1
G28: 2362.57
B30: What we owe | C30: Amount we pay a month | G30: 2362.57
A31: Synchrony Bank Payment - Mattress (automatic) | B31: 4025 | C31: 69 | G31: 2930.11
G32: 2883.06
G33: 8175.74
G35: 8175.74
G36: 1716
G37: 6459.74

Sheet October 2020
A1: October 2020 Monthly Budget
A2: Income: | B2: 1st half of month | C2: 2nd half of month | F2: what we make 1st half of month | G2: what we owe 1st half of month | H2: money left over
A3: Brian | B3: 3277.24 | C3: 3277.24 | F3: =B3+B4 -> 4718.77 | G3: =C9+C10+C11+C12+C13+C14+C15+C16 -> 3565.2 | H3: =F3-G3 -> 1153.57
A4: Lauren | B4: 1441.53 | C4: 1441.53
F5: what we make 2nd half of month | G5: what we owe 2nd half of month | H5: money left over
F6: =B3+B4 -> 4718.77 | G6: =C19+C20+C21+C22+C23+C24+C25+C26 -> 1709.82 | H6: =F6-G6 -> 3008.95
A7: Expenses: | B7: Due Date: | C7: Expense Cost:
A8: 1st half of month:
A9: Mortgage Payment (automatic) | B9: 1st of each month | C9: 2256.87
A10: Direct TV (automatic) | B10: 2nd of each month | C10: 123.1
A11: Arkansas Protection Services | B11: Paid Quartly | C11: 40 | F11: Average for two week span
A12: Mohela Student Interest Loan (automatic) | B12: 6th of each month | C12: 542.02 | F12: =(H3+H6)/2 -> 2081.26
A13: Travlers Insurance | B13: 7th of each month | C13: 148.03
A14: Spotify USA (automatic) | B14: 9th of each month | C14: 14.18
A15: BBVA Finance (automatic) | B15: 12th of each month | C15: 434.01
A16: Disney+(automatic) | B16: 13th of each month | C16: 6.99
A18: 2nd half of month:
A19: Swyft Internet(automatic) | B19: 15th of each month | C19: 98.74
A20: Tahoe Payment (automatic) | B20: 16th of each month | C20: 483.15
A21: Greenbrier Water, trash payment | B21: 18th of each month | C21: 80
A22: At&t Payment (automatic) | B22: 22nd of each month | C22: 210.53
A23: Entergy Payment (automatic) | B23: 27th of each month | C23: 356.41
A24: Netflix | B24: 28th of each month | C24: 17.51
A25: Pool Loan Payment(automatic) | B25: 29th of each month | C25: 342.81
A26: Lawn Mower | B26: 29th of each month | C26: 120.67
B30: What we owe | C30: Amount we pay a month
A31: Synchrony Bank Payment - Mattress (automatic) | B31: 4025 | C31: 69

Sheet September 2020
A1: September 2020 Monthly Budget
A2: Income: | B2: 1st half of month | C2: 2nd half of month | F2: what we make 1st half of month | G2: what we owe 1st half of month | H2: money left over
A3: Brian | B3: 3277.24 | C3: 3277.24 | F3: =B3+B4 -> 4718.77 | G3: =C9+C10+C11+C12+C13+C14+C15+C16 -> 3538.22 | H3: =F3-G3 -> 1180.55
A4: Lauren | B4: 1441.53 | C4: 1441.53
F5: what we make 2nd half of month | G5: what we owe 2nd half of month | H5: money left over
F6: =B3+B4 -> 4718.77 | G6: =C19+C20+C21+C22+C23+C24+C25+C26 -> 1633.17 | H6: =F6-G6 -> 3085.6
A7: Expenses: | B7: Due Date: | C7: Expense Cost:
A8: 1st half of month:
A9: Mortgage Payment (automatic) | B9: 1st of each month | C9: 2256.87
A10: Direct TV (automatic) | B10: 2nd of each month | C10: 96.12
A11: Arkansas Protection Services | B11: Paid Quartly | C11: 40 | F11: Average for two week span
A12: Mohela Student Interest Loan (automatic) | B12: 6th of each month | C12: 542.02 | F12: =(H3+H6)/2 -> 2133.075
A13: Travlers Insurance | B13: 7th of each month | C13: 148.03
A14: Spotify USA (automatic) | B14: 9th of each month | C14: 14.18
A15: BBVA Finance (automatic) | B15: 12th of each month | C15: 434.01
A16: Disney+(automatic) | B16: 13th of each month | C16: 6.99
A18: 2nd half of month:
A19: Swyft Internet(automatic) | B19: 15th of each month | C19: 98.74
A20: Tahoe Payment (automatic) | B20: 16th of each month | C20: 483.15
A21: Greenbrier Water, trash payment | B21: 18th of each month | C21: 80
A22: At&t Payment (automatic) | B22: 22nd of each month | C22: 212.75
A23: Entergy Payment (automatic) | B23: 27th of each month | C23: 277.54
A24: Netflix | B24: 28th of each month | C24: 17.51
A25: Pool Loan Payment(automatic) | B25: 29th of each month | C25: 342.81
A26: Lawn Mower | B26: 29th of each month | C26: 120.67
B30: What we owe | C30: Amount we pay a month
A31: Synchrony Bank Payment - Mattress (automatic) | B31: 4025 | C31: 69

Sheet August 2020
A1: August 2020 Monthly Budget
A2: Income: | B2: 1st half of month | C2: 2nd half of month | F2: what we make 1st half of month | G2: what we owe 1st half of month | H2: money left over
A3: Brian | B3: 3277.24 | C3: 3277.24 | F3: =B3+B4 -> 4759.74 | G3: =C9+C10+C11+C12+C13+C14+C15+C16 -> 3538.22 | H3: =F3-G3 -> 1221.52
A4: Lauren | B4: 1482.5 | C4: 1482.5
F5: what we make 2nd half of month | G5: what we owe 2nd half of month | H5: money left over
F6: =B3+B4 -> 4759.74 | G6: =C19+C20+C21+C22+C23+C24+C25 -> 1605.59 | H6: =F6-G6 -> 3154.15
A7: Expenses: | B7: Due Date: | C7: Expense Cost:
A8: 1st half of month:
A9: Mortgage Payment (automatic) | B9: 1st of each month | C9: 2256.87
A10: Direct TV (automatic) | B10: 2nd of each month | C10: 96.12
A11: Arkansas Protection Services | B11: Paid Quartly | C11: 40 | F11: Average for two week span
A12: Mohela Student Interest Loan (automatic) | B12: 6th of each month | C12: 542.02 | F12: =(H3+H6)/2 -> 2187.835
A13: Travlers Insurance | B13: 7th of each month | C13: 148.03
A14: Spotify USA (automatic) | B14: 9th of each month | C14: 14.18
A15: BBVA Finance (automatic) | B15: 12th of each month | C15: 434.01
A16: Disney+(automatic) | B16: 13th of each month | C16: 6.99
A18: 2nd half of month:
A19: Swyft Internet(automatic) | B19: 15th of each month | C19: 98.74
A20: Tahoe Payment (automatic) | B20: 16th of each month | C20: 483.15
A21: Greenbrier Water, trash payment | B21: 18th of each month | C21: 194.24
A22: At&t Payment (automatic) | B22: 22nd of each month | C22: 212.75
A23: Entergy Payment (automatic) | B23: 27th of each month | C23: 256.39
A24: Netflix | B24: 28th of each month | C24: 17.51
A25: Pool Loan Payment(automatic) | B25: 29th of each month | C25: 342.81
B29: What we owe | C29: Amount we pay a month
A30: Synchrony Bank Payment - Mattress (automatic) | B30: 4025 | C30: 69
A34: Pool Loan: Pay 70$ to principle a month(I think) | C34: Savings account: 740 a month | F34: 740 plus 342 how long to catch back up
A35: 43500 | C35: 2821.98 | F35: 631.98
A36: =A35-70 -> 43430 | C36: =C35+740 -> 3561.98 | F36: =F35+740+342 -> 1713.98
A37: =A36-70 -> 43360 | C37: =C36+740 -> 4301.98 | F37: =F36+740+342 -> 2795.98
A38: =A37-70 -> 43290 | C38: =C37+740 -> 5041.98 | F38: =F37+740+342 -> 3877.98
A39: =A38-70 -> 43220 | C39: =C38+740 -> 5781.98 | F39: =F38+740+342 -> 4959.98
A40: =A39-70 -> 43150 | C40: =C39+740 -> 6521.98 | F40: =F39+740+342 -> 6041.98
A41: =A40-70 -> 43080 | C41: =C40+740 -> 7261.98 | F41: =F40+740+342 -> 7123.98
A42: =A41-70 -> 43010 | C42: =C41+740 -> 8001.98 | F42: =F41+740+342 -> 8205.98
A43: =A42-70 -> 42940 | C43: =C42+740 -> 8741.98 | F43: =F42+740+342 -> 9287.98
A44: =A43-70 -> 42870 | C44: =C43+740 -> 9481.98 | F44: =F43+740+342 -> 10369.98
A45: =A44-70 -> 42800 | C45: =C44+740 -> 10221.98 | F45: =F44+740+342 -> 11451.98
A46: =A45-70 -> 42730 | C46: =C45+740 -> 10961.98 | F46: =F45+740+342 -> 12533.98
A47: =A46-70 -> 42660 | C47: =C46+740 -> 11701.98 | F47: =F46+740+342 -> 13615.98
...

Sheet July 2020
A1: July 2020 Monthly Budget
A2: Income: | B2: 1st half of month | C2: 2nd half of month | F2: what we make 1st half of month | G2: what we owe 1st half of month | H2: money left over
A3: Brian | B3: 3277.24 | C3: 3277.24 | F3: =B3+B4 -> 4574.72 | G3: =C9+C10+C11+C12+C13+C14+C15+C16 -> 3534.94 | H3: =F3-G3 -> 1039.78
A4: Lauren | B4: 1297.48 | C4: 1297.48
F5: what we make 2nd half of month | G5: what we owe 2nd half of month | H5: money left over
F6: =B3+B4 -> 4574.72 | G6: =C19+C20+C21+C22+C23+C24+C25 -> 1613.59 | H6: =F6-G6 -> 2961.13
A7: Expenses: | B7: Due Date: | C7: Expense Cost:
A8: 1st half of month:
A9: Mortgage Payment (automatic) | B9: 1st of each month | C9: 2256.87
A10: Direct TV (automatic) | B10: 2nd of each month | C10: 96.12
A11: Arkansas Protection Services | B11: Paid Quartly | C11: 40 | F11: Average for two week span
A12: Mohela Student Interest Loan (automatic) | B12: 6th of each month | C12: 542.02 | F12: =(H3+H6)/2 -> 2000.455
A13: Travlers Insurance | B13: 7th of each month | C13: 148.03
A14: Spotify USA (automatic) | B14: 9th of each month | C14: 10.9
A15: BBVA Finance (automatic) | B15: 12th of each month | C15: 434.01
A16: Disney+(automatic) | B16: 13th of each month | C16: 6.99
A18: 2nd half of month:
A19: Swyft Internet(automatic) | B19: 15th of each month | C19: 98.74
A20: Tahoe Payment (automatic) | B20: 16th of each month | C20: 483.15
A21: Greenbrier Water, trash payment | B21: 18th of each month | C21: 40
A22: At&t Payment (automatic) | B22: 22nd of each month | C22: 157.84
A23: Entergy Payment (automatic) | B23: 27th of each month | C23: 473.54
A24: Netflix | B24: 28th of each month | C24: 17.51
A25: Pool Loan Payment(automatic) | B25: 25th of each month | C25: 342.81
B29: What we owe | C29: Amount we pay a month
A30: Synchrony Bank Payment - Mattress (automatic) | B30: 4025 | C30: 69

Sheet June 2020
A1: June 2020 Monthly Budget
A2: Income: | B2: 1st half of month | C2: 2nd half of month | F2: what we make 1st half of month | G2: what we owe 1st half of month | H2: money left over
A3: Brian | B3: 3277.24 | C3: 3277.24 | F3: =B3+B4 -> 4574.72 | G3: =C9+C10+C11+C12+C13+C14+C15+C16 -> 3502.85 | H3: =F3-G3 -> 1071.87
A4: Lauren | B4: 1297.48 | C4: 1297.48
F5: what we make 2nd half of month | G5: what we owe 2nd half of month | H5: money left over
F6: =B3+B4 -> 4574.72 | G6: =C19+C20+C21+C22+C23+C24+C25 -> 1385.83 | H6: =F6-G6 -> 3188.89
A7: Expenses: | B7: Due Date: | C7: Expense Cost:
A8: 1st half of month:
A9: Mortgage Payment (automatic) | B9: 1st of each month | C9: 2256.87
A10: Direct TV (automatic) | B10: 2nd of each month | C10: 96.12
A11: Arkansas Protection Services | B11: Paid Quartly | C11: 40 | F11: Average for two week span
A12: Mohela Student Interest Loan (automatic) | B12: 6th of each month | C12: 542.02 | F12: =(H3+H6)/2 -> 2130.38
A13: Travlers Insurance | B13: 7th of each month | C13: 115.94
A14: Spotify USA (automatic) | B14: 9th of each month | C14: 10.9
A15: BBVA Finance (automatic) | B15: 12th of each month | C15: 434.01
A16: Disney+(automatic) | B16: 13th of each month | C16: 6.99
A18: 2nd half of month:
A19: Swyft Internet(automatic) | B19: 15th of each month | C19: 97.47
A20: Tahoe Payment (automatic) | B20: 16th of each month | C20: 483.15
A21: Greenbrier Water, trash payment | B21: 18th of each month
A22: At&t Payment (automatic) | B22: 22nd of each month | C22: 157.84
A23: Pool Loan Payment(automatic) | B23: 25th of each month | C23: 354.43
A24: Entergy Payment (automatic) | B24: 27th of each month | C24: 275.43
A25: Netflix | B25: 28th of each month | C25: 17.51
B29: What we owe | C29: Amount we pay a month
A30: Synchrony Bank Payment - Mattress (automatic) | B30: 4025 | C30: 69
A31: Amex CC(will be 0$ soon) | B31: 6140.59 | C31: 65

Sheet May 2020
A1: May 2020 Monthly Budget
A2: Income: | B2: 1st half of month | C2: 2nd half of month | F2: what we make 1st half of month | G2: what we owe 1st half of month | H2: money left over
A3: Brian | B3: 3277.24 | C3: 3277.24 | F3: =B3+B4 -> 4574.72 | G3: =C9+C10+C11+C12+C13+C14+C15+C16+C17+C18+C19 -> 3802.75 | H3: =F3-G3 -> 771.97
A4: Lauren | B4: 1297.48 | C4: 1297.48
F5: what we make 2nd half of month | G5: what we owe 2nd half of month | H5: money left over
F6: =B3+B4 -> 4574.72 | G6: =C22+C23+C24+C25+C26 -> 992.67 | H6: =F6-G6 -> 3582.05
A7: Expenses: | B7: Due Date: | C7: Expense Cost:
A8: 1st half of month:
A9: Mortgage Payment (automatic) | B9: 1st of each month | C9: 2558.18
A10: Direct TV (automatic) | B10: 2nd of each month | C10: 72.71
A11: Arkansas Protection Services | C11: 40 | F11: Average for two week span
A12: Mohela Student Interest Loan (automatic) | B12: 6th of each month | C12: 542.02 | F12: =(H3+H6)/2 -> 2177.01
A13: Travlers Insurance | B13: 7th of each month | C13: 137.94
A15: Nelnet Loan #1(automatic) | B15: 9th of each month
A16: Spotify USA (automatic) | B16: 9th of each month | C16: 10.9
A17: BBVA Finance (automatic) | B17: 12th of each month | C17: 434.01
A18: Disney+(automatic) | B18: 13th of each month | C18: 6.99
A19: NelNet loan #2(automatic)(Gov't defer till 9/20/20) | B19: 15th of each month
A21: 2nd half of month:
A22: Tahoe Payment (automatic) | B22: 16th of each month | C22: 483.15
A23: Greenbrier Water, trash payment | B23: 18th of each month | C23: 33.4
A24: At&t Payment (automatic) | B24: 22nd of each month | C24: 196.61
A25: Entergy Payment (automatic) | B25: 27th of each month | C25: 262
A26: Netflix | B26: 28th of each month | C26: 17.51
B30: What we owe | C30: Amount we pay a month | F30: Lauren Student Loan | G30: 4629.58
A31: Citi Black Card payment (automatic) | B31: 9721.73 | C31: 183 | F31: Monthly payment | G31: 474.31
A32: US Bank loan payment (automatic) | B32: 12766.06 | C32: 411.14
A33: Synchrony Bank Payment - Mattress (automatic) | B33: 4025 | C33: 69
A34: Amex CC(will be 0$ soon) | B34: 6140.59 | C34: 65
A35: Lowes CC | B35: 0
A36: Sam's Club CC | B36: 0
A37: Amazon CC (4272.00 available) (will be 0$ soon) | B37: 0

Sheet April 2020
A1: April 2020 Monthly Budget
A2: Income: | B2: 1st half of month | C2: 2nd half of month | F2: what we make 1st half of month | G2: what we owe 1st half of month | H2: money left over
A3: Brian | B3: 3277.24 | C3: 3277.24 | F3: =B3+B4 -> 4574.72 | G3: =C9+C10+C11+C12+C13+C14+C15+C16+C17 -> 3342.33 | H3: =F3-G3 -> 1232.39
A4: Lauren | B4: 1297.48 | C4: 1297.48
F5: what we make 2nd half of month | G5: what we owe 2nd half of month | H5: money left over
F6: =B3+B4 -> 4574.72 | G6: =C20+C21+C22+C23+C24 -> 961.52 | H6: =F6-G6 -> 3613.2
A7: Expenses: | B7: Due Date: | C7: Expense Cost:
A8: 1st half of month:
A9: New House Payment #1 (automatic) | B9: 1st of each month | C9: 1568.84
A10: Direct TV (automatic) | B10: 2nd of each month | C10: 72.71
A11: Vivint Payment(automatic) | B11: 3rd of each month | C11: 33.69 | F11: Average for two week span
A12: Mohela Student Interest Loan (automatic) | B12: 6th of each month | C12: 542.02 | F12: =(H3+H6)/2 -> 2422.795
A13: Travlers Insurance | B13: 7th of each month | C13: 148.82
A14: Windstream Internet Payment (automatic) | B14: 7th of each month | C14: 67.93
A15: Nelnet Loan #1(automatic) | B15: 9th of each month | C15: 184.4
A16: BBVA Finance (automatic) | B16: 12th of each month | C16: 434.01
A17: NelNet loan #2(automatic)(Gov't defer till 9/20/20) | B17: 15th of each month | C17: 289.91
A19: 2nd half of month:
A20: Tahoe Payment (automatic) | B20: 16th of each month | C20: 484
A21: Greenbrier Water, trash payment | B21: 18th of each month | C21: 33.4
A22: At&t Payment (automatic) | B22: 22nd of each month | C22: 196.61
A23: Entergy Payment (automatic) | B23: 27th of each month | C23: 230
A24: Netflix | B24: 28th of each month | C24: 17.51
B28: What we owe | C28: Amount we pay a month | F28: 279900
A29: Citi Black Card payment (automatic) | B29: 9871.73 | C29: 183 | F29: 11196 | G29: 4% Realtor Fee
A30: US Bank loan payment (automatic) | B30: 12489.9 | C30: 411.14 | F30: 268704
A31: Synchrony Bank Payment - Mattress (automatic) | B31: 4094 | C31: 69
A32: Amex CC(will be 0$ soon) | B32: 1913.44 | C32: 65 | F32: 266704 | G32: (minus 2,000 for painting house)
A33: Lowes CC (will be 0$ soon) | B33: 590.81 | F33: 29654 | G33: (CC debt)
A34: Sam's Club CC (will be 0$ soon) | B34: 0 | F34: 237,050‬
A35: Amazon CC (4272.00 available) (will be 0$ soon) | B35: 694.27
F36: 237050
F37: 21495 | G37: 5% down payment
F38: 215,555‬
F40: 215555
F41: 205638.6 | G41: (what we owe on the house)
F42: 9,916.4‬ | G42: Potential profit after all things!

Sheet March 2020
A1: March 2020 Monthly Budget
A2: Income: | B2: 1st half of month | C2: 2nd half of month | F2: what we make 1st half of month | G2: what we owe 1st half of month | H2: money left over
A3: Brian | B3: 3277.24 | C3: 3277.24 | F3: =B3+B4 -> 4574.72 | G3: =C9+C10+C11+C12+C13+C14+C15+C16+C17 -> 3323.74 | H3: =F3-G3 -> 1250.98
A4: Lauren | B4: 1297.48 | C4: 1297.48
F5: what we make 2nd half of month | G5: what we owe 2nd half of month | H5: money left over
F6: =B3+B4 -> 4574.72 | G6: =C20+C21+C22+C23+C24 -> 948.75 | H6: =F6-G6 -> 3625.97
A7: Expenses: | B7: Due Date: | C7: Expense Cost:
A8: 1st half of month:
A9: New House Payment #1 (automatic) | B9: 1st of each month | C9: 1568.84
A10: Direct TV (automatic) | B10: 2nd of each month | C10: 72.71
A11: Vivint Payment(automatic) | B11: 3rd of each month | C11: 32.1 | F11: Average for two week span
A12: Mohela Student Interest Loan (automatic) | B12: 6th of each month | C12: 542.02 | F12: =(H3+H6)/2 -> 2438.475
